Workbook

Sheet Cover
A1: 150 kg/day module — cost and P&L
A2: Closed-loop leach / EW / pyro / BMED / ZnBr2 pack. One 40HC wet + one 20HC thermal + yard.
A4: Sheets
A5: Assumptions | B5: All yellow cells are inputs. Blue text = typed. Black = formula. Green = cross-sheet.
A6: Capex | B6: Installed cost of one module. Contingency and working capital separate.
A7: Opex | B7: Annual cash cost. Labor, power, membranes, chemicals, maintenance.
A8: Yields | B8: kg product per wet tonne by feedstock. From ELECTRICAL.md assays.
A9: P&L | B9: Annual P&L for seven feedstocks at 300 operating days.
A10: Cash | B10: Simple cash yield, payback, and EBIT margin vs feedstock.
A12: Basis
A13: Prices: LME / COMEX / spot 25–26 Sep 2026, applied at a cathode/powder discount. Gold $4,284/oz, silver $64.31/oz, copper ~$6.73/lb LME, nickel $7.42/lb, zinc $1.77/lb, lead $0.88/lb, tin $24.50/lb. Fe as shredded equivalent. This is not a bank model. No offtake contracts, no ITC, no tipping-contract tenor. Change the yellow cells.
A18: Verdict in one line
A19: The module makes money on mixed WEEE and PCB-rich feed because gold/copper pay the capex. MSW and bulk landfill pay you a gate fee and still lose money at this scale — auxiliaries and labor do not shrink when the metal grade does. Tailings at 150 kg/day are a science project, not a P&L.

Sheet Assumptions
A1: Assumptions — edit yellow cells
A3: Item | B3: Value | C3: Unit | D3: Note
A4: Throughput | B4: 150 | C4: kg/day | D4: Wet feed into hopper
A5: Operating days | B5: 300 | C5: d/y | D5: Rest is maintenance / strip / membrane swap
A6: Availability | B6: 0.85 | C6: frac | D6: Applied on top of 300 days for cash days
A7: Labor headcount | B7: 1.5 | C7: FTE | D7: One operator + shared mechanic
A8: Loaded labor | B8: 80000 | C8: USD/FTE-y | D8: Dallas-area loaded
A9: Grid power price | B9: 0.1 | C9: USD/kWh | D9: Imported residual after PV
A10: PV export price | B10: 0.04 | C10: USD/kWh | D10: If net exporter; unused in base
A11: PV array | B11: 70 | C11: kW-STC | D11: Ground mount
A12: PV yield | B12: 1500 | C12: kWh/kW-y | D12: North Texas fixed tilt, derated
A13: Maintenance | B13: 0.03 | C13: frac capex/y | D13: Excludes membranes
A14: Insurance + lease | B14: 0.015 | C14: frac capex/y | D14: Yard pad + liability
A15: Membrane spend | B15: 18000 | C15: USD/y | D15: EW + BMED + ZnBr2 CEM
... A20: Contingency on capex | B20: 0.2 | C20: frac | D20: First module
A22: Product prices (USD per kg unless noted)
A23: Product | B23: Price | C23: Unit | D23: Note
A24: Au | B24: 137700 | C24: USD/kg | D24: Spot $4,284/oz × 0.95 recovery to saleable
A25: Ag | B25: 2068 | C25: USD/kg | D25: Spot $64.31/oz × 0.95
A26: Pd | B26: 38200 | C26: USD/kg | D26: Spot ~$1,251/oz × 0.95
A27: Cu | B27: 14.1 | C27: USD/kg | D27: LME ~$6.73/lb × 0.95 cathode
A28: Ni | B28: 14.7 | C28: USD/kg | D28: LME ~$7.42/lb × 0.90
A29: Sn | B29: 48.6 | C29: USD/kg | D29: LME ~$24.50/lb × 0.90
A30: Zn | B30: 3.51 | C30: USD/kg | D30: LME ~$1.77/lb × 0.90
A31: Pb | B31: 1.75 | C31: USD/kg | D31: LME ~$0.88/lb × 0.90
A32: Fe | B32: 0.4 | C32: USD/kg | D32: Shred-equivalent powder
A33: Al cake | B33: 0.35 | C33: USD/kg | D33: Hydroxide to refiner / farm
A34: Oil cuts | B34: 0.45 | C34: USD/kg | D34: Dirty pyro oil, not diesel
A35: Silicate | B35: 0.12 | C35: USD/kg | D35: Na-silicate liquor
A36: Grit | B36: 0.02 | C36: USD/kg | D36: Aggregate / media
A38: Feedstock cash (positive = you pay, negative = gate fee received)
A39: Feedstock | B39: USD/wet t | C39: Unit | D39: Note
A40: Mixed WEEE | B40: 150 | C40: USD/t | D40: You buy a mixed stream
A41: PCB-rich | B41: 600 | C41: USD/t | D41: Boards command a price
A42: MSW | B42: -55 | C42: USD/t | D42: Tipping fee to you
A43: Landfill bulk | B43: 30 | C43: USD/t | D43: Excavate + haul
A44: Landfill TBM / WEEE cell | B44: 45 | C44: USD/t | D44: Selective mining cost
A45: Cu tailings 0.3% | B45: 8 | C45: USD/t | D45: Rehandle on site
A46: Au tailings | B46: 12 | C46: USD/t | D46: Rehandle on site
A48: Module energy intensity (kWh per wet tonne, includes 9 kW aux at 150 kg/d)
...

Sheet Capex
A1: Installed capex — one module
A3: Line | B3: USD | C3: Class | D3: Note
A4: 40HC + 20HC shells, doors, bund, twist-locks | B4: 28000 | C4: civil | D4: Painted, new or A-grade used
A5: Pad, berm, trench drains, grounding | B5: 45000 | C5: civil | D5: 12.2 × 6 m plus yard
A6: Hopper, shredder, conveyors | B6: 38000 | C6: mech
A7: Leach CSTRs, VDF, vibratory, pumps | B7: 72000 | C7: wet | D7: CPVC/PVDF vessels
A8: EW aisle 9 cells + polish rack | B8: 95000 | C8: wet | D8: Membranes first fill included
A9: BMED stack + CRU + totes | B9: 85000 | C9: wet
A10: Oil line: dryer, induction pyro, quench, still | B10: 110000 | C10: thermal | D10: Ti shell + iron auger
A11: Afterburner, burnout rotary, mill, digest | B11: 65000 | C11: thermal
A12: Scrubbers, baghouse, ducts, stacks | B12: 48000 | C12: air | D12: Plant Cl2 + battery Br2
A13: Rectifiers, MCC, ATS, plant main | B13: 42000 | C13: elec
A14: Sol-Ark 60K-3P-480V | B14: 18000 | C14: power | D14: Inverter only
A15: PV 70 kW ground mount + rack + DC | B15: 84000 | C15: power | D15: ~1.20 USD/W-STC installed
A16: ZnBr2 stack + tanks + BMS gateway | B16: 72000 | C16: power | D16: 120 kWh / 60 kW custom
A17: Instruments, PLC, hoods | B17: 35000 | C17: elec
A18: First-fill liquor and complexer | B18: 18000 | C18: wc | D18: Salria + ZnBr2 + NaOH
A19: Engineering / drawings / permitting | B19: 55000 | C19: soft | D19: First article
A21: Subtotal installed | B21: =SUM(B4:B19) -> 910000
A22: Contingency | B22: =B21*Assumptions!B20 -> 182000
A23: Total capex | B23: =B21+B22 -> 1092000
A24: Working capital | B24: =Assumptions!B19*Opex!B20 -> 15931.2
A25: Capital employed | B25: =B23+B24 -> 1107931.2

Sheet Opex
A1: Annual cash opex (fixed + energy that does not depend on feedstock grade)
A3: Line | B3: USD/y | C3: Note
A4: Labor | B4: =Assumptions!B7*Assumptions!B8 -> 120000 | C4: FTE × loaded
A5: Maintenance | B5: =Assumptions!B13*Capex!B23 -> 32760 | C5: 3% of total capex
A6: Insurance + pad lease | B6: =Assumptions!B14*Capex!B23 -> 16380 | C6: 1.5% of total capex
A7: Membranes | B7: =Assumptions!B15 -> 18000 | C7: Input
A8: Chemicals | B8: =Assumptions!B16 -> 12000 | C8: Input
A9: Fixed cash opex | B9: =SUM(B4:B8) -> 199140
A11: Energy is computed per feedstock on the P&L sheet (kWh/t × t/y − PV).
A13: PV kWh/y | B13: =Assumptions!B60 -> 105000
A20: Fixed cash used by working-capital formula | B20: =B9 -> 199140

Sheet Yields
A1: Saleable kg per wet tonne of feed
A2: From ELECTRICAL.md working assays. Yellow = editable. Totals on P&L use these × tonnes/year.
A4: Feedstock | B4: Au_g | C4: Ag_g | D4: Pd_g | E4: Cu_kg | F4: Ni_kg | G4: Sn_kg | H4: Zn_kg | I4: Pb_kg | J4: Fe_kg | K4: Alcake_kg | L4: Oil_kg | M4: Silicate_kg | N4: Grit_kg
A5: Mixed WEEE | B5: 45 | C5: 180 | D5: 8 | E5: 63 | F5: 8 | G5: 6 | H5: 8 | I5: 8 | J5: 212 | K5: 70 | L5: 150 | M5: 80 | N5: 120
A6: PCB-rich | B6: 135 | C6: 720 | D6: 40 | E6: 112 | F6: 6 | G6: 10 | H6: 4 | I6: 12 | J6: 56 | K6: 50 | L6: 170 | M6: 150 | N6: 170
A7: MSW | B7: 0 | C7: 0 | D7: 0 | E7: 1.5 | F7: 0.2 | G7: 0.1 | H7: 0.5 | I7: 0.3 | J7: 30 | K7: 25 | L7: 180 | M7: 30 | N7: 50
A8: Landfill bulk | B8: 0.2 | C8: 1 | D8: 0 | E8: 1 | F8: 0.1 | G8: 0.05 | H8: 0.4 | I8: 0.2 | J8: 18 | K8: 20 | L8: 80 | M8: 80 | N8: 440
A9: Landfill TBM / WEEE cell | B9: 18 | C9: 72 | D9: 3 | E9: 27 | F9: 4 | G9: 3 | H9: 4 | I9: 4 | J9: 110 | K9: 50 | L9: 120 | M9: 80 | N9: 200
A10: Cu tailings 0.3% | B10: 0.08 | C10: 1.5 | D10: 0 | E10: 2.4 | F10: 0.05 | G10: 0 | H10: 0.1 | I10: 0.05 | J10: 20 | K10: 40 | L10: 0 | M10: 200 | N10: 650
A11: Au tailings | B11: 0.35 | C11: 1.8 | D11: 0 | E11: 0.4 | F11: 0 | G11: 0 | H11: 0 | I11: 0 | J11: 8 | K11: 30 | L11: 0 | M11: 200 | N11: 680
A13: Au_g / Ag_g / Pd_g are grams per wet tonne. Multiply by price/1000 on the P&L.

Sheet P&L
A1: Annual P&L by feedstock — 150 kg/day module
A2: Green cells pull Assumptions / Yields / Capex / Opex. Change yellow inputs, this sheet follows.
B4: Mixed WEEE | C4: PCB-rich | D4: MSW | E4: LF bulk | F4: LF TBM | G4: Cu tailings | H4: Au tailings
A5: Wet tonnes / year | B5: =Assumptions!$B$59 -> 38.25 | C5: =Assumptions!$B$59 -> 38.25 | D5: =Assumptions!$B$59 -> 38.25 | E5: =Assumptions!$B$59 -> 38.25 | F5: =Assumptions!$B$59 -> 38.25 | G5: =Assumptions!$B$59 -> 38.25 | H5: =Assumptions!$B$59 -> 38.25
A6: Revenue
A7: Au | B7: =Yields!B5*$B5*Assumptions!$B$24/1000 -> 237016.12 | C7: =Yields!B6*$B5*Assumptions!$B$24/1000 -> 711048.38 | D7: =Yields!B7*$B5*Assumptions!$B$24/1000 -> 0 | E7: =Yields!B8*$B5*Assumptions!$B$24/1000 -> 1053.405 | F7: =Yields!B9*$B5*Assumptions!$B$24/1000 -> 94806.45 | G7: =Yields!B10*$B5*Assumptions!$B$24/1000 -> 421.362 | H7: =Yields!B11*$B5*Assumptions!$B$24/1000 -> 1843.4588
A8: Ag | B8: =Yields!C5*$B5*Assumptions!$B$25/1000 -> 14238.18 | C8: =Yields!C6*$B5*Assumptions!$B$25/1000 -> 56952.72 | D8: =Yields!C7*$B5*Assumptions!$B$25/1000 -> 0 | E8: =Yields!C8*$B5*Assumptions!$B$25/1000 -> 79.101 | F8: =Yields!C9*$B5*Assumptions!$B$25/1000 -> 5695.272 | G8: =Yields!C10*$B5*Assumptions!$B$25/1000 -> 118.6515 | H8: =Yields!C11*$B5*Assumptions!$B$25/1000 -> 142.3818
A9: Pd | B9: =Yields!D5*$B5*Assumptions!$B$26/1000 -> 11689.2 | C9: =Yields!D6*$B5*Assumptions!$B$26/1000 -> 58446 | D9: =Yields!D7*$B5*Assumptions!$B$26/1000 -> 0 | E9: =Yields!D8*$B5*Assumptions!$B$26/1000 -> 0 | F9: =Yields!D9*$B5*Assumptions!$B$26/1000 -> 4383.45 | G9: =Yields!D10*$B5*Assumptions!$B$26/1000 -> 0 | H9: =Yields!D11*$B5*Assumptions!$B$26/1000 -> 0
A10: Cu | B10: =Yields!E5*$B5*Assumptions!$B$27 -> 33977.475 | C10: =Yields!E6*$B5*Assumptions!$B$27 -> 60404.4 | D10: =Yields!E7*$B5*Assumptions!$B$27 -> 808.9875 | E10: =Yields!E8*$B5*Assumptions!$B$27 -> 539.325 | F10: =Yields!E9*$B5*Assumptions!$B$27 -> 14561.775 | G10: =Yields!E10*$B5*Assumptions!$B$27 -> 1294.38 | H10: =Yields!E11*$B5*Assumptions!$B$27 -> 215.73
A11: Ni | B11: =Yields!F5*$B5*Assumptions!$B$28 -> 4498.2 | C11: =Yields!F6*$B5*Assumptions!$B$28 -> 3373.65 | D11: =Yields!F7*$B5*Assumptions!$B$28 -> 112.455 | E11: =Yields!F8*$B5*Assumptions!$B$28 -> 56.2275 | F11: =Yields!F9*$B5*Assumptions!$B$28 -> 2249.1 | G11: =Yields!F10*$B5*Assumptions!$B$28 -> 28.11375 | H11: =Yields!F11*$B5*Assumptions!$B$28 -> 0
A12: Sn | B12: =Yields!G5*$B5*Assumptions!$B$29 -> 11153.7 | C12: =Yields!G6*$B5*Assumptions!$B$29 -> 18589.5 | D12: =Yields!G7*$B5*Assumptions!$B$29 -> 185.895 | E12: =Yields!G8*$B5*Assumptions!$B$29 -> 92.9475 | F12: =Yields!G9*$B5*Assumptions!$B$29 -> 5576.85 | G12: =Yields!G10*$B5*Assumptions!$B$29 -> 0 | H12: =Yields!G11*$B5*Assumptions!$B$29 -> 0
A13: Zn | B13: =Yields!H5*$B5*Assumptions!$B$30 -> 1074.06 | C13: =Yields!H6*$B5*Assumptions!$B$30 -> 537.03 | D13: =Yields!H7*$B5*Assumptions!$B$30 -> 67.12875 | E13: =Yields!H8*$B5*Assumptions!$B$30 -> 53.703 | F13: =Yields!H9*$B5*Assumptions!$B$30 -> 537.03 | G13: =Yields!H10*$B5*Assumptions!$B$30 -> 13.42575 | H13: =Yields!H11*$B5*Assumptions!$B$30 -> 0
A14: Pb | B14: =Yields!I5*$B5*Assumptions!$B$31 -> 535.5 | C14: =Yields!I6*$B5*Assumptions!$B$31 -> 803.25 | D14: =Yields!I7*$B5*Assumptions!$B$31 -> 20.08125 | E14: =Yields!I8*$B5*Assumptions!$B$31 -> 13.3875 | F14: =Yields!I9*$B5*Assumptions!$B$31 -> 267.75 | G14: =Yields!I10*$B5*Assumptions!$B$31 -> 3.346875 | H14: =Yields!I11*$B5*Assumptions!$B$31 -> 0
A15: Fe | B15: =Yields!J5*$B5*Assumptions!$B$32 -> 3243.6 | C15: =Yields!J6*$B5*Assumptions!$B$32 -> 856.8 | D15: =Yields!J7*$B5*Assumptions!$B$32 -> 459 | E15: =Yields!J8*$B5*Assumptions!$B$32 -> 275.4 | F15: =Yields!J9*$B5*Assumptions!$B$32 -> 1683 | G15: =Yields!J10*$B5*Assumptions!$B$32 -> 306 | H15: =Yields!J11*$B5*Assumptions!$B$32 -> 122.4
A16: Al cake | B16: =Yields!K5*$B5*Assumptions!$B$33 -> 937.125 | C16: =Yields!K6*$B5*Assumptions!$B$33 -> 669.375 | D16: =Yields!K7*$B5*Assumptions!$B$33 -> 334.6875 | E16: =Yields!K8*$B5*Assumptions!$B$33 -> 267.75 | F16: =Yields!K9*$B5*Assumptions!$B$33 -> 669.375 | G16: =Yields!K10*$B5*Assumptions!$B$33 -> 535.5 | H16: =Yields!K11*$B5*Assumptions!$B$33 -> 401.625
A17: Oil cuts | B17: =Yields!L5*$B5*Assumptions!$B$34 -> 2581.875 | C17: =Yields!L6*$B5*Assumptions!$B$34 -> 2926.125 | D17: =Yields!L7*$B5*Assumptions!$B$34 -> 3098.25 | E17: =Yields!L8*$B5*Assumptions!$B$34 -> 1377 | F17: =Yields!L9*$B5*Assumptions!$B$34 -> 2065.5 | G17: =Yields!L10*$B5*Assumptions!$B$34 -> 0 | H17: =Yields!L11*$B5*Assumptions!$B$34 -> 0
A18: Silicate | B18: =Yields!M5*$B5*Assumptions!$B$35 -> 367.2 | C18: =Yields!M6*$B5*Assumptions!$B$35 -> 688.5 | D18: =Yields!M7*$B5*Assumptions!$B$35 -> 137.7 | E18: =Yields!M8*$B5*Assumptions!$B$35 -> 367.2 | F18: =Yields!M9*$B5*Assumptions!$B$35 -> 367.2 | G18: =Yields!M10*$B5*Assumptions!$B$35 -> 918 | H18: =Yields!M11*$B5*Assumptions!$B$35 -> 918
A19: Grit | B19: =Yields!N5*$B5*Assumptions!$B$36 -> 91.8 | C19: =Yields!N6*$B5*Assumptions!$B$36 -> 130.05 | D19: =Yields!N7*$B5*Assumptions!$B$36 -> 38.25 | E19: =Yields!N8*$B5*Assumptions!$B$36 -> 336.6 | F19: =Yields!N9*$B5*Assumptions!$B$36 -> 153 | G19: =Yields!N10*$B5*Assumptions!$B$36 -> 497.25 | H19: =Yields!N11*$B5*Assumptions!$B$36 -> 520.2
A20: Product revenue | B20: =SUM(B7:B19) -> 321404.04 | C20: =SUM(C7:C19) -> 915425.78 | D20: =SUM(D7:D19) -> 5262.435 | E20: =SUM(E7:E19) -> 4512.0465 | F20: =SUM(F7:F19) -> 133015.75 | G20: =SUM(G7:G19) -> 4136.0299 | H20: =SUM(H7:H19) -> 4163.7955
A21: Gate fee / feedstock purchase | B21: =-Assumptions!B40*$B$5 -> -5737.5 | C21: =-Assumptions!B41*$B$5 -> -22950 | D21: =-Assumptions!B42*$B$5 -> 2103.75 | E21: =-Assumptions!B43*$B$5 -> -1147.5 | F21: =-Assumptions!B44*$B$5 -> -1721.25 | G21: =-Assumptions!B45*$B$5 -> -306 | H21: =-Assumptions!B46*$B$5 -> -459
A22: Total revenue | B22: =B20+B21 -> 315666.54 | C22: =C20+C21 -> 892475.78 | D22: =D20+D21 -> 7366.185 | E22: =E20+E21 -> 3364.5465 | F22: =F20+F21 -> 131294.5 | G22: =G20+G21 -> 3830.0299 | H22: =H20+H21 -> 3704.7955
A24: Cash costs
A25: Fixed cash opex | B25: =Opex!$B$9 -> 199140 | C25: =Opex!$B$9 -> 199140 | D25: =Opex!$B$9 -> 199140 | E25: =Opex!$B$9 -> 199140 | F25: =Opex!$B$9 -> 199140 | G25: =Opex!$B$9 -> 199140 | H25: =Opex!$B$9 -> 199140
A26: Energy imported | B26: =MAX(0,Assumptions!B50*$B$5-Assumptions!$B$60)*Assumptions!$B$9 -> 822 | C26: =MAX(0,Assumptions!B51*$B$5-Assumptions!$B$60)*Assumptions!$B$9 -> 0 | D26: =MAX(0,Assumptions!B52*$B$5-Assumptions!$B$60)*Assumptions!$B$9 -> 0 | E26: =MAX(0,Assumptions!B53*$B$5-Assumptions!$B$60)*Assumptions!$B$9 -> 0 | F26: =MAX(0,Assumptions!B54*$B$5-Assumptions!$B$60)*Assumptions!$B$9 -> 0 | G26: =MAX(0,Assumptions!B55*$B$5-Assumptions!$B$60)*Assumptions!$B$9 -> 0 | H26: =MAX(0,Assumptions!B56*$B$5-Assumptions!$B$60)*Assumptions!$B$9 -> 0
A27: Total cash opex | B27: =B25+B26 -> 199962 | C27: =C25+C26 -> 199140 | D27: =D25+D26 -> 199140 | E27: =E25+E26 -> 199140 | F27: =F25+F26 -> 199140 | G27: =G25+G26 -> 199140 | H27: =H25+H26 -> 199140
A29: EBITDA | B29: =B22-B27 -> 115704.54 | C29: =C22-C27 -> 693335.78 | D29: =D22-D27 -> -191773.82 | E29: =E22-E27 -> -195775.45 | F29: =F22-F27 -> -67845.498 | G29: =G22-G27 -> -195309.97 | H29: =H22-H27 -> -195435.2
A30: Depreciation | B30: =Capex!$B$23/Assumptions!$B$17 -> 109200 | C30: =Capex!$B$23/Assumptions!$B$17 -> 109200 | D30: =Capex!$B$23/Assumptions!$B$17 -> 109200 | E30: =Capex!$B$23/Assumptions!$B$17 -> 109200 | F30: =Capex!$B$23/Assumptions!$B$17 -> 109200 | G30: =Capex!$B$23/Assumptions!$B$17 -> 109200 | H30: =Capex!$B$23/Assumptions!$B$17 -> 109200
A31: EBIT | B31: =B29-B30 -> 6504.54 | C31: =C29-C30 -> 584135.78 | D31: =D29-D30 -> -300973.82 | E31: =E29-E30 -> -304975.45 | F31: =F29-F30 -> -177045.5 | G31: =G29-G30 -> -304509.97 | H31: =H29-H30 -> -304635.2
A32: Tax on positive EBIT | B32: =MAX(0,B31)*Assumptions!$B$18 -> 1365.9534 | C32: =MAX(0,C31)*Assumptions!$B$18 -> 122668.51 | D32: =MAX(0,D31)*Assumptions!$B$18 -> 0 | E32: =MAX(0,E31)*Assumptions!$B$18 -> 0 | F32: =MAX(0,F31)*Assumptions!$B$18 -> 0 | G32: =MAX(0,G31)*Assumptions!$B$18 -> 0 | H32: =MAX(0,H31)*Assumptions!$B$18 -> 0
A33: Net income | B33: =B31-B32 -> 5138.5866 | C33: =C31-C32 -> 461467.26 | D33: =D31-D32 -> -300973.82 | E33: =E31-E32 -> -304975.45 | F33: =F31-F32 -> -177045.5 | G33: =G31-G32 -> -304509.97 | H33: =H31-H32 -> -304635.2
A35: Cash from operations (NI + dep) | B35: =B33+B30 -> 114338.59 | C35: =C33+C30 -> 570667.26 | D35: =D33+D30 -> -191773.82 | E35: =E33+E30 -> -195775.45 | F35: =F33+F30 -> -67845.498 | G35: =G33+G30 -> -195309.97 | H35: =H33+H30 -> -195435.2
A36: Simple payback years | B36: =IF(B35<=0,"n.m.",Capex!$B$25/B35) -> 9.6899151 | C36: =IF(C35<=0,"n.m.",Capex!$B$25/C35) -> 1.9414662 | D36: =IF(D35<=0,"n.m.",Capex!$B$25/D35) -> n.m. | E36: =IF(E35<=0,"n.m.",Capex!$B$25/E35) -> n.m. | F36: =IF(F35<=0,"n.m.",Capex!$B$25/F35) -> n.m. | G36: =IF(G35<=0,"n.m.",Capex!$B$25/G35) -> n.m. | H36: =IF(H35<=0,"n.m.",Capex!$B$25/H35) -> n.m.
A37: EBIT margin | B37: =IF(B22=0,0,B31/B22) -> 0.020605732 | C37: =IF(C22=0,0,C31/C22) -> 0.65451163 | D37: =IF(D22=0,0,D31/D22) -> -40.858846 | E37: =IF(E22=0,0,E31/E22) -> -90.643852 | F37: =IF(F22=0,0,F31/F22) -> -1.3484609 | G37: =IF(G22=0,0,G31/G22) -> -79.505899 | H37: =IF(H22=0,0,H31/H22) -> -82.227265
A38: Revenue / t feed | B38: =IF($B$5=0,0,B22/$B$5) -> 8252.72 | C38: =IF($B$5=0,0,C22/$B$5) -> 23332.7 | D38: =IF($B$5=0,0,D22/$B$5) -> 192.58 | E38: =IF($B$5=0,0,E22/$B$5) -> 87.962 | F38: =IF($B$5=0,0,F22/$B$5) -> 3432.536 | G38: =IF($B$5=0,0,G22/$B$5) -> 100.1315 | H38: =IF($B$5=0,0,H22/$B$5) -> 96.8574
A39: Cash opex / t feed | B39: =IF($B$5=0,0,B27/$B$5) -> 5227.7647 | C39: =IF($B$5=0,0,C27/$B$5) -> 5206.2745 | D39: =IF($B$5=0,0,D27/$B$5) -> 5206.2745 | E39: =IF($B$5=0,0,E27/$B$5) -> 5206.2745 | F39: =IF($B$5=0,0,F27/$B$5) -> 5206.2745 | G39: =IF($B$5=0,0,G27/$B$5) -> 5206.2745 | H39: =IF($B$5=0,0,H27/$B$5) -> 5206.2745
A41: n.m. = not meaningful (operations do not generate cash). Gate fee on MSW is revenue (negative feedstock price). Gold in mixed WEEE and PCB-rich is most of product revenue; iron is most of the mass and almost none of the money.

Sheet Cash
A1: Capital and break-even
A3: Total capex | B3: =Capex!B23 -> 1092000
A4: Working capital | B4: =Capex!B24 -> 15931.2
A5: Capital employed | B5: =Capex!B25 -> 1107931.2
A6: Annual depreciation | B6: =Capex!B23/Assumptions!B17 -> 109200
A7: Fixed cash opex | B7: =Opex!B9 -> 199140
A8: PV generation | B8: =Assumptions!B60 -> 105000 | C8: kWh/y
A10: What the model is saying
A11: A first module at ~$1.0–1.3M installed is a precious-metal machine that also happens to eat the rest of the shred. Mixed WEEE and PCB-rich clear labor and aux because Au/Ag/Cu pay. Everything else is a utilization problem: the 9 kW of fans and 1.5 FTE do not care that the tonne was dirt. Scale fixes that — 500 kg/day cuts aux-per-tonne by ~3× and still uses one inverter class if you add a second wet box. Do not bid landfill-mining or tailings as the sole feedstock for this envelope. Use them as swing feed on days the WEEE truck is late.
A18: Prices dated 25–26 Sep 2026 (LME/COMEX/spot). Electrolyte and membrane life are guesses until the first stack has a year on it.
